Workbook

Sheet Main
A1: Gun 1 | B1: Ammo Type | C1: Barrel Type | X1: =Data!X1 | Y1: =Data!Y1 | Z1: =Data!Z1 | AA1: =Data!AA1 | AB1: =Data!AB1 | AC1: =Data!AC1 | AD1: =Data!AD1 | AE1: =Data!AE1 | ... AH1: =Data!AH1
A2: SCW-10 | B2: Normal | C2: Normal
A4: Gun 2 | B4: Ammo Type | C4: Barrel Type
A5: KTS100 MK8 | B5: Normal | C5: Extended
A7: Comparison (gun 1 - gun 2, TTK, ms) | J7: Comparison (gun 1 - gun 2, time required to fire the shots, ms)
A8: =A19 -> Num hs vs dist (m) | B8: =B19 -> 0 | C8: =C19 -> 10 | D8: =D19 -> 20 | E8: =E19 -> 35 | F8: =F19 -> 50 | G8: =G19 -> 70 | H8: =H19 -> 80 | J8: =J19 -> Num hs vs dist (m) | K8: =K19 -> 0 | L8: =L19 -> 10 | M8: =M19 -> 20 | N8: =N19 -> 35 | O8: =O19 -> 50 | P8: =P19 -> 70 | Q8: =Q19 -> 80
A9: =A20 -> 0 | B9: =B20-B31 -> -200.19455 | C9: =C20-C31 -> -108.52789 | D9: =D20-D31 -> -108.52789 | E9: =E20-E31 -> -116.92607 | F9: =F20-F31 -> -8.5927367 | G9: =G20-G31 -> 8.07393 | H9: =H20-H31 -> -0.32425422 | J9: =J20 -> 0 | K9: =K20-K31 -> -200.19455 | L9: =L20-L31 -> -125.19455 | M9: =M20-M31 -> -125.19455 | N9: =N20-N31 -> -166.92607 | O9: =O20-O31 -> -91.92607 | P9: =P20-P31 -> -91.92607 | Q9: =Q20-Q31 -> -133.65759
A10: =A21 -> 1 | B10: =B21-B32 -> -200.19455 | C10: =C21-C32 -> -108.52789 | D10: =D21-D32 -> -108.52789 | E10: =E21-E32 -> -116.92607 | F10: =F21-F32 -> -8.5927367 | G10: =G21-G32 -> 8.07393 | H10: =H21-H32 -> -0.32425422 | J10: =J21 -> 1 | K10: =K21-K32 -> -200.19455 | L10: =L21-L32 -> -125.19455 | M10: =M21-M32 -> -125.19455 | N10: =N21-N32 -> -166.92607 | O10: =O21-O32 -> -91.92607 | P10: =P21-P32 -> -91.92607 | Q10: =Q21-Q32 -> -133.65759
A11: =A22 -> 2 | B11: =B22-B33 -> -200.19455 | C11: =C22-C33 -> -108.52789 | D11: =D22-D33 -> -108.52789 | E11: =E22-E33 -> -116.92607 | F11: =F22-F33 -> -8.5927367 | G11: =G22-G33 -> 8.07393 | H11: =H22-H33 -> -0.32425422 | J11: =J22 -> 2 | K11: =K22-K33 -> -200.19455 | L11: =L22-L33 -> -125.19455 | M11: =M22-M33 -> -125.19455 | N11: =N22-N33 -> -166.92607 | O11: =O22-O33 -> -91.92607 | P11: =P22-P33 -> -91.92607 | Q11: =Q22-Q33 -> -133.65759
A12: =A23 -> 3 | B12: =B23-B34 -> -83.463035 | C12: =C23-C34 -> -66.796368 | D12: =D23-D34 -> -66.796368 | E12: =E23-E34 -> -75.194553 | F12: =F23-F34 -> 33.138781 | G12: =G23-G34 -> 49.805447 | H12: =H23-H34 -> 41.407263 | J12: =J23 -> 3 | K12: =K23-K34 -> -83.463035 | L12: =L23-L34 -> -83.463035 | M12: =M23-M34 -> -83.463035 | N12: =N23-N34 -> -125.19455 | O12: =O23-O34 -> -50.194553 | P12: =P23-P34 -> -50.194553 | Q12: =Q23-Q34 -> -91.92607
A13: =A24 -> 4 | B13: =B24-B35 -> -83.463035 | C13: =C24-C35 -> -66.796368 | D13: =D24-D35 -> -66.796368 | E13: =E24-E35 -> -75.194553 | F13: =F24-F35 -> 33.138781 | G13: =G24-G35 -> 49.805447 | H13: =H24-H35 -> 41.407263 | J13: =J24 -> 4 | K13: =K24-K35 -> -83.463035 | L13: =L24-L35 -> -83.463035 | M13: =M24-M35 -> -83.463035 | N13: =N24-N35 -> -125.19455 | O13: =O24-O35 -> -50.194553 | P13: =P24-P35 -> -50.194553 | Q13: =Q24-Q35 -> -91.92607
A14: =A25 -> 5 | B14: =B25-B36 -> -83.463035 | C14: =C25-C36 -> -66.796368 | D14: =D25-D36 -> -66.796368 | E14: =E25-E36 -> -75.194553 | F14: =F25-F36 -> 33.138781 | G14: =G25-G36 -> 49.805447 | H14: =H25-H36 -> 41.407263 | J14: =J25 -> 5 | K14: =K25-K36 -> -83.463035 | L14: =L25-L36 -> -83.463035 | M14: =M25-M36 -> -83.463035 | N14: =N25-N36 -> -125.19455 | O14: =O25-O36 -> -50.194553 | P14: =P25-P36 -> -50.194553 | Q14: =Q25-Q36 -> -91.92607
A15: =A26 -> 6 | B15: =B26-B37 -> -83.463035 | C15: =C26-C37 -> -66.796368 | D15: =D26-D37 -> -66.796368 | E15: =E26-E37 -> -75.194553 | F15: =F26-F37 -> 33.138781 | G15: =G26-G37 -> 49.805447 | H15: =H26-H37 -> 41.407263 | J15: =J26 -> 6 | K15: =K26-K37 -> -83.463035 | L15: =L26-L37 -> -83.463035 | M15: =M26-M37 -> -83.463035 | N15: =N26-N37 -> -125.19455 | O15: =O26-O37 -> -50.194553 | P15: =P26-P37 -> -50.194553 | Q15: =Q26-Q37 -> -91.92607
A16: =A27 -> 7 | B16: =B27-B38 -> -83.463035 | C16: =C27-C38 -> -66.796368 | D16: =D27-D38 -> -66.796368 | E16: =E27-E38 -> -75.194553 | F16: =F27-F38 -> 33.138781 | G16: =G27-G38 -> 49.805447 | H16: =H27-H38 -> 41.407263 | J16: =J27 -> 7 | K16: =K27-K38 -> -83.463035 | L16: =L27-L38 -> -83.463035 | M16: =M27-M38 -> -83.463035 | N16: =N27-N38 -> -125.19455 | O16: =O27-O38 -> -50.194553 | P16: =P27-P38 -> -50.194553 | Q16: =Q27-Q38 -> -91.92607
A18: G1 TTK Total | J18: G1 TTK Shots
A19: Num hs vs dist (m) | B19: 0 | C19: 10 | D19: 20 | E19: 35 | F19: 50 | G19: 70 | H19: 80 | J19: Num hs vs dist (m) | K19: 0 | L19: 10 | M19: 20 | N19: 35 | O19: 50 | P19: 70 | Q19: 80
A20: 0 | B20: =K20+0 -> 150 | C20: {=L20+INDEX('Intermediate Sums'!$B$17:$AP$17, MATCH(TRUE, 'Intermediate Sums'!$B$16:$AP$16 > C$19, 0))} -> 241.66667 | D20: {=M20+INDEX('Intermediate Sums'!$B$17:$AP$17, MATCH(TRUE, 'Intermediate Sums'!$B$16:$AP$16 > D$19, 0))} -> 258.33333 | E20: {=N20+INDEX('Intermediate Sums'!$B$17:$AP$17, MATCH(TRUE, 'Intermediate Sums'!$B$16:$AP$16 > E$19, 0))} -> 383.33333 | F20: {=O20+INDEX('Intermediate Sums'!$B$17:$AP$17, MATCH(TRUE, 'Intermediate Sums'!$B$16:$AP$16 > F$19, 0))} -> 491.66667 | G20: {=P20+INDEX('Intermediate Sums'!$B$17:$AP$17, MATCH(TRUE, 'Intermediate Sums'!$B$16:$AP$16 > G$19, 0))} -> 541.66667 | H20: {=Q20+INDEX('Intermediate Sums'!$B$17:$AP$17, MATCH(TRUE, 'Intermediate Sums'!$B$16:$AP$16 > H$19, 0))} -> 650 | J20: 0 | K20: =if($J20>=CEILING(100/'Intermediate Sums'!B$43,1), ($J20-1)*'Intermediate Sums'!$B$26, (CEILING('Intermediate Sums'!B56/'Intermediate Sums'!B$49,1)+$J20-1)*'Intermediate Sums'!$B$26) -> 150 | L20: =if($J20>=CEILING(100/'Intermediate Sums'!C$43,1), ($J20-1)*'Intermediate Sums'!$B$26, (CEILING('Intermediate Sums'!C56/'Intermediate Sums'!C$49,1)+$J20-1)*'Intermediate Sums'!$B$26) -> 225 | M20: =if($J20>=CEILING(100/'Intermediate Sums'!D$43,1), ($J20-1)*'Intermediate Sums'!$B$26, (CEILING('Intermediate Sums'!D56/'Intermediate Sums'!D$49,1)+$J20-1)*'Intermediate Sums'!$B$26) -> 225 | N20: =if($J20>=CEILING(100/'Intermediate Sums'!E$43,1), ($J20-1)*'Intermediate Sums'!$B$26, (CEILING('Intermediate Sums'!E56/'Intermediate Sums'!E$49,1)+$J20-1)*'Intermediate Sums'!$B$26) -> 300 | O20: =if($J20>=CEILING(100/'Intermediate Sums'!F$43,1), ($J20-1)*'Intermediate Sums'!$B$26, (CEILING('Intermediate Sums'!F56/'Intermediate Sums'!F$49,1)+$J20-1)*'Intermediate Sums'!$B$26) -> 375 | P20: =if($J20>=CEILING(100/'Intermediate Sums'!G$43,1), ($J20-1)*'Intermediate Sums'!$B$26, (CEILING('Intermediate Sums'!G56/'Intermediate Sums'!G$49,1)+$J20-1)*'Intermediate Sums'!$B$26) -> 375 | Q20: =if($J20>=CEILING(100/'Intermediate Sums'!H$43,1), ($J20-1)*'Intermediate Sums'!$B$26, (CEILING('Intermediate Sums'!H56/'Intermediate Sums'!H$49,1)+$J20-1)*'Intermediate Sums'!$B$26) -> 450
A21: 1 | B21: =K21+0 -> 150 | C21: {=L21+INDEX('Intermediate Sums'!$B$17:$AP$17, MATCH(TRUE, 'Intermediate Sums'!$B$16:$AP$16 > C$19, 0))} -> 241.66667 | D21: {=M21+INDEX('Intermediate Sums'!$B$17:$AP$17, MATCH(TRUE, 'Intermediate Sums'!$B$16:$AP$16 > D$19, 0))} -> 258.33333 | E21: {=N21+INDEX('Intermediate Sums'!$B$17:$AP$17, MATCH(TRUE, 'Intermediate Sums'!$B$16:$AP$16 > E$19, 0))} -> 383.33333 | F21: {=O21+INDEX('Intermediate Sums'!$B$17:$AP$17, MATCH(TRUE, 'Intermediate Sums'!$B$16:$AP$16 > F$19, 0))} -> 491.66667 | G21: {=P21+INDEX('Intermediate Sums'!$B$17:$AP$17, MATCH(TRUE, 'Intermediate Sums'!$B$16:$AP$16 > G$19, 0))} -> 541.66667 | H21: {=Q21+INDEX('Intermediate Sums'!$B$17:$AP$17, MATCH(TRUE, 'Intermediate Sums'!$B$16:$AP$16 > H$19, 0))} -> 650 | J21: 1 | K21: =if($J20>=CEILING(100/'Intermediate Sums'!B$43,1), K20, if($J21>=CEILING(100/'Intermediate Sums'!B$43,1), ($J21-1)*'Intermediate Sums'!$B$26, (CEILING('Intermediate Sums'!B57/'Intermediate Sums'!B$49,1)+$J21-1)*'Intermediate Sums'!$B$26)) -> 150 | L21: =if($J20>=CEILING(100/'Intermediate Sums'!C$43,1), L20, if($J21>=CEILING(100/'Intermediate Sums'!C$43,1), ($J21-1)*'Intermediate Sums'!$B$26, (CEILING('Intermediate Sums'!C57/'Intermediate Sums'!C$49,1)+$J21-1)*'Intermediate Sums'!$B$26)) -> 225 | M21: =if($J20>=CEILING(100/'Intermediate Sums'!D$43,1), M20, if($J21>=CEILING(100/'Intermediate Sums'!D$43,1), ($J21-1)*'Intermediate Sums'!$B$26, (CEILING('Intermediate Sums'!D57/'Intermediate Sums'!D$49,1)+$J21-1)*'Intermediate Sums'!$B$26)) -> 225 | N21: =if($J20>=CEILING(100/'Intermediate Sums'!E$43,1), N20, if($J21>=CEILING(100/'Intermediate Sums'!E$43,1), ($J21-1)*'Intermediate Sums'!$B$26, (CEILING('Intermediate Sums'!E57/'Intermediate Sums'!E$49,1)+$J21-1)*'Intermediate Sums'!$B$26)) -> 300 | O21: =if($J20>=CEILING(100/'Intermediate Sums'!F$43,1), O20, if($J21>=CEILING(100/'Intermediate Sums'!F$43,1), ($J21-1)*'Intermediate Sums'!$B$26, (CEILING('Intermediate Sums'!F57/'Intermediate Sums'!F$49,1)+$J21-1)*'Intermediate Sums'!$B$26)) -> 375 | P21: =if($J20>=CEILING(100/'Intermediate Sums'!G$43,1), P20, if($J21>=CEILING(100/'Intermediate Sums'!G$43,1), ($J21-1)*'Intermediate Sums'!$B$26, (CEILING('Intermediate Sums'!G57/'Intermediate Sums'!G$49,1)+$J21-1)*'Intermediate Sums'!$B$26)) -> 375 | Q21: =if($J20>=CEILING(100/'Intermediate Sums'!H$43,1), Q20, if($J21>=CEILING(100/'Intermediate Sums'!H$43,1), ($J21-1)*'Intermediate Sums'!$B$26, (CEILING('Intermediate Sums'!H57/'Intermediate Sums'!H$49,1)+$J21-1)*'Intermediate Sums'!$B$26)) -> 450
A22: 2 | B22: =K22+0 -> 150 | C22: {=L22+INDEX('Intermediate Sums'!$B$17:$AP$17, MATCH(TRUE, 'Intermediate Sums'!$B$16:$AP$16 > C$19, 0))} -> 241.66667 | D22: {=M22+INDEX('Intermediate Sums'!$B$17:$AP$17, MATCH(TRUE, 'Intermediate Sums'!$B$16:$AP$16 > D$19, 0))} -> 258.33333 | E22: {=N22+INDEX('Intermediate Sums'!$B$17:$AP$17, MATCH(TRUE, 'Intermediate Sums'!$B$16:$AP$16 > E$19, 0))} -> 383.33333 | F22: {=O22+INDEX('Intermediate Sums'!$B$17:$AP$17, MATCH(TRUE, 'Intermediate Sums'!$B$16:$AP$16 > F$19, 0))} -> 491.66667 | G22: {=P22+INDEX('Intermediate Sums'!$B$17:$AP$17, MATCH(TRUE, 'Intermediate Sums'!$B$16:$AP$16 > G$19, 0))} -> 541.66667 | H22: {=Q22+INDEX('Intermediate Sums'!$B$17:$AP$17, MATCH(TRUE, 'Intermediate Sums'!$B$16:$AP$16 > H$19, 0))} -> 650 | J22: 2 | K22: =if($J21>=CEILING(100/'Intermediate Sums'!B$43,1), K21, if($J22>=CEILING(100/'Intermediate Sums'!B$43,1), ($J22-1)*'Intermediate Sums'!$B$26, (CEILING('Intermediate Sums'!B58/'Intermediate Sums'!B$49,1)+$J22-1)*'Intermediate Sums'!$B$26)) -> 150 | L22: =if($J21>=CEILING(100/'Intermediate Sums'!C$43,1), L21, if($J22>=CEILING(100/'Intermediate Sums'!C$43,1), ($J22-1)*'Intermediate Sums'!$B$26, (CEILING((100-$J$22*'Intermediate Sums'!C$43)/'Intermediate Sums'!C$49,1)+$J22-1)*'Intermediate Sums'!$B$26)) -> 225 | M22: =if($J21>=CEILING(100/'Intermediate Sums'!D$43,1), M21, if($J22>=CEILING(100/'Intermediate Sums'!D$43,1), ($J22-1)*'Intermediate Sums'!$B$26, (CEILING((100-$J$22*'Intermediate Sums'!D$43)/'Intermediate Sums'!D$49,1)+$J22-1)*'Intermediate Sums'!$B$26)) -> 225 | N22: =if($J21>=CEILING(100/'Intermediate Sums'!E$43,1), N21, if($J22>=CEILING(100/'Intermediate Sums'!E$43,1), ($J22-1)*'Intermediate Sums'!$B$26, (CEILING((100-$J$22*'Intermediate Sums'!E$43)/'Intermediate Sums'!E$49,1)+$J22-1)*'Intermediate Sums'!$B$26)) -> 300 | O22: =if($J21>=CEILING(100/'Intermediate Sums'!F$43,1), O21, if($J22>=CEILING(100/'Intermediate Sums'!F$43,1), ($J22-1)*'Intermediate Sums'!$B$26, (CEILING((100-$J$22*'Intermediate Sums'!F$43)/'Intermediate Sums'!F$49,1)+$J22-1)*'Intermediate Sums'!$B$26)) -> 375 | P22: =if($J21>=CEILING(100/'Intermediate Sums'!G$43,1), P21, if($J22>=CEILING(100/'Intermediate Sums'!G$43,1), ($J22-1)*'Intermediate Sums'!$B$26, (CEILING((100-$J$22*'Intermediate Sums'!G$43)/'Intermediate Sums'!G$49,1)+$J22-1)*'Intermediate Sums'!$B$26)) -> 375 | Q22: =if($J21>=CEILING(100/'Intermediate Sums'!H$43,1), Q21, if($J22>=CEILING(100/'Intermediate Sums'!H$43,1), ($J22-1)*'Intermediate Sums'!$B$26, (CEILING((100-$J$22*'Intermediate Sums'!H$43)/'Intermediate Sums'!H$49,1)+$J22-1)*'Intermediate Sums'!$B$26)) -> 450
A23: 3 | B23: =K23+0 -> 150 | C23: {=L23+INDEX('Intermediate Sums'!$B$17:$AP$17, MATCH(TRUE, 'Intermediate Sums'!$B$16:$AP$16 > C$19, 0))} -> 166.66667 | D23: {=M23+INDEX('Intermediate Sums'!$B$17:$AP$17, MATCH(TRUE, 'Intermediate Sums'!$B$16:$AP$16 > D$19, 0))} -> 183.33333 | E23: {=N23+INDEX('Intermediate Sums'!$B$17:$AP$17, MATCH(TRUE, 'Intermediate Sums'!$B$16:$AP$16 > E$19, 0))} -> 308.33333 | F23: {=O23+INDEX('Intermediate Sums'!$B$17:$AP$17, MATCH(TRUE, 'Intermediate Sums'!$B$16:$AP$16 > F$19, 0))} -> 416.66667 | G23: {=P23+INDEX('Intermediate Sums'!$B$17:$AP$17, MATCH(TRUE, 'Intermediate Sums'!$B$16:$AP$16 > G$19, 0))} -> 466.66667 | H23: {=Q23+INDEX('Intermediate Sums'!$B$17:$AP$17, MATCH(TRUE, 'Intermediate Sums'!$B$16:$AP$16 > H$19, 0))} -> 575 | J23: 3 | K23: =if($J22>=CEILING(100/'Intermediate Sums'!B$43,1), K22, if($J23>=CEILING(100/'Intermediate Sums'!B$43,1), ($J23-1)*'Intermediate Sums'!$B$26, (CEILING('Intermediate Sums'!B59/'Intermediate Sums'!B$49,1)+$J23-1)*'Intermediate Sums'!$B$26)) -> 150 | L23: =if($J22>=CEILING(100/'Intermediate Sums'!C$43,1), L22, if($J23>=CEILING(100/'Intermediate Sums'!C$43,1), ($J23-1)*'Intermediate Sums'!$B$26, (CEILING('Intermediate Sums'!C59/'Intermediate Sums'!C$49,1)+$J23-1)*'Intermediate Sums'!$B$26)) -> 150 | M23: =if($J22>=CEILING(100/'Intermediate Sums'!D$43,1), M22, if($J23>=CEILING(100/'Intermediate Sums'!D$43,1), ($J23-1)*'Intermediate Sums'!$B$26, (CEILING('Intermediate Sums'!D59/'Intermediate Sums'!D$49,1)+$J23-1)*'Intermediate Sums'!$B$26)) -> 150 | N23: =if($J22>=CEILING(100/'Intermediate Sums'!E$43,1), N22, if($J23>=CEILING(100/'Intermediate Sums'!E$43,1), ($J23-1)*'Intermediate Sums'!$B$26, (CEILING('Intermediate Sums'!E59/'Intermediate Sums'!E$49,1)+$J23-1)*'Intermediate Sums'!$B$26)) -> 225 | O23: =if($J22>=CEILING(100/'Intermediate Sums'!F$43,1), O22, if($J23>=CEILING(100/'Intermediate Sums'!F$43,1), ($J23-1)*'Intermediate Sums'!$B$26, (CEILING('Intermediate Sums'!F59/'Intermediate Sums'!F$49,1)+$J23-1)*'Intermediate Sums'!$B$26)) -> 300 | P23: =if($J22>=CEILING(100/'Intermediate Sums'!G$43,1), P22, if($J23>=CEILING(100/'Intermediate Sums'!G$43,1), ($J23-1)*'Intermediate Sums'!$B$26, (CEILING('Intermediate Sums'!G59/'Intermediate Sums'!G$49,1)+$J23-1)*'Intermediate Sums'!$B$26)) -> 300 | Q23: =if($J22>=CEILING(100/'Intermediate Sums'!H$43,1), Q22, if($J23>=CEILING(100/'Intermediate Sums'!H$43,1), ($J23-1)*'Intermediate Sums'!$B$26, (CEILING('Intermediate Sums'!H59/'Intermediate Sums'!H$49,1)+$J23-1)*'Intermediate Sums'!$B$26)) -> 375
A24: 4 | B24: =K24+0 -> 150 | C24: {=L24+INDEX('Intermediate Sums'!$B$17:$AP$17, MATCH(TRUE, 'Intermediate Sums'!$B$16:$AP$16 > C$19, 0))} -> 166.66667 | D24: {=M24+INDEX('Intermediate Sums'!$B$17:$AP$17, MATCH(TRUE, 'Intermediate Sums'!$B$16:$AP$16 > D$19, 0))} -> 183.33333 | E24: {=N24+INDEX('Intermediate Sums'!$B$17:$AP$17, MATCH(TRUE, 'Intermediate Sums'!$B$16:$AP$16 > E$19, 0))} -> 308.33333 | F24: {=O24+INDEX('Intermediate Sums'!$B$17:$AP$17, MATCH(TRUE, 'Intermediate Sums'!$B$16:$AP$16 > F$19, 0))} -> 416.66667 | G24: {=P24+INDEX('Intermediate Sums'!$B$17:$AP$17, MATCH(TRUE, 'Intermediate Sums'!$B$16:$AP$16 > G$19, 0))} -> 466.66667 | H24: {=Q24+INDEX('Intermediate Sums'!$B$17:$AP$17, MATCH(TRUE, 'Intermediate Sums'!$B$16:$AP$16 > H$19, 0))} -> 575 | J24: 4 | K24: =if($J23>=CEILING(100/'Intermediate Sums'!B$43,1), K23, if($J24>=CEILING(100/'Intermediate Sums'!B$43,1), ($J24-1)*'Intermediate Sums'!$B$26, (CEILING('Intermediate Sums'!B60/'Intermediate Sums'!B$49,1)+$J24-1)*'Intermediate Sums'!$B$26)) -> 150 | L24: =if($J23>=CEILING(100/'Intermediate Sums'!C$43,1), L23, if($J24>=CEILING(100/'Intermediate Sums'!C$43,1), ($J24-1)*'Intermediate Sums'!$B$26, (CEILING('Intermediate Sums'!C60/'Intermediate Sums'!C$49,1)+$J24-1)*'Intermediate Sums'!$B$26)) -> 150 | M24: =if($J23>=CEILING(100/'Intermediate Sums'!D$43,1), M23, if($J24>=CEILING(100/'Intermediate Sums'!D$43,1), ($J24-1)*'Intermediate Sums'!$B$26, (CEILING('Intermediate Sums'!D60/'Intermediate Sums'!D$49,1)+$J24-1)*'Intermediate Sums'!$B$26)) -> 150 | N24: =if($J23>=CEILING(100/'Intermediate Sums'!E$43,1), N23, if($J24>=CEILING(100/'Intermediate Sums'!E$43,1), ($J24-1)*'Intermediate Sums'!$B$26, (CEILING('Intermediate Sums'!E60/'Intermediate Sums'!E$49,1)+$J24-1)*'Intermediate Sums'!$B$26)) -> 225 | O24: =if($J23>=CEILING(100/'Intermediate Sums'!F$43,1), O23, if($J24>=CEILING(100/'Intermediate Sums'!F$43,1), ($J24-1)*'Intermediate Sums'!$B$26, (CEILING('Intermediate Sums'!F60/'Intermediate Sums'!F$49,1)+$J24-1)*'Intermediate Sums'!$B$26)) -> 300 | P24: =if($J23>=CEILING(100/'Intermediate Sums'!G$43,1), P23, if($J24>=CEILING(100/'Intermediate Sums'!G$43,1), ($J24-1)*'Intermediate Sums'!$B$26, (CEILING('Intermediate Sums'!G60/'Intermediate Sums'!G$49,1)+$J24-1)*'Intermediate Sums'!$B$26)) -> 300 | Q24: =if($J23>=CEILING(100/'Intermediate Sums'!H$43,1), Q23, if($J24>=CEILING(100/'Intermediate Sums'!H$43,1), ($J24-1)*'Intermediate Sums'!$B$26, (CEILING('Intermediate Sums'!H60/'Intermediate Sums'!H$49,1)+$J24-1)*'Intermediate Sums'!$B$26)) -> 375
A25: 5 | B25: =K25+0 -> 150 | C25: {=L25+INDEX('Intermediate Sums'!$B$17:$AP$17, MATCH(TRUE, 'Intermediate Sums'!$B$16:$AP$16 > C$19, 0))} -> 166.66667 | D25: {=M25+INDEX('Intermediate Sums'!$B$17:$AP$17, MATCH(TRUE, 'Intermediate Sums'!$B$16:$AP$16 > D$19, 0))} -> 183.33333 | E25: {=N25+INDEX('Intermediate Sums'!$B$17:$AP$17, MATCH(TRUE, 'Intermediate Sums'!$B$16:$AP$16 > E$19, 0))} -> 308.33333 | F25: {=O25+INDEX('Intermediate Sums'!$B$17:$AP$17, MATCH(TRUE, 'Intermediate Sums'!$B$16:$AP$16 > F$19, 0))} -> 416.66667 | G25: {=P25+INDEX('Intermediate Sums'!$B$17:$AP$17, MATCH(TRUE, 'Intermediate Sums'!$B$16:$AP$16 > G$19, 0))} -> 466.66667 | H25: {=Q25+INDEX('Intermediate Sums'!$B$17:$AP$17, MATCH(TRUE, 'Intermediate Sums'!$B$16:$AP$16 > H$19, 0))} -> 575 | J25: 5 | K25: =if($J24>=CEILING(100/'Intermediate Sums'!B$43,1), K24, if($J25>=CEILING(100/'Intermediate Sums'!B$43,1), ($J25-1)*'Intermediate Sums'!$B$26, (CEILING('Intermediate Sums'!B61/'Intermediate Sums'!B$49,1)+$J25-1)*'Intermediate Sums'!$B$26)) -> 150 | L25: =if($J24>=CEILING(100/'Intermediate Sums'!C$43,1), L24, if($J25>=CEILING(100/'Intermediate Sums'!C$43,1), ($J25-1)*'Intermediate Sums'!$B$26, (CEILING('Intermediate Sums'!C61/'Intermediate Sums'!C$49,1)+$J25-1)*'Intermediate Sums'!$B$26)) -> 150 | M25: =if($J24>=CEILING(100/'Intermediate Sums'!D$43,1), M24, if($J25>=CEILING(100/'Intermediate Sums'!D$43,1), ($J25-1)*'Intermediate Sums'!$B$26, (CEILING('Intermediate Sums'!D61/'Intermediate Sums'!D$49,1)+$J25-1)*'Intermediate Sums'!$B$26)) -> 150 | N25: =if($J24>=CEILING(100/'Intermediate Sums'!E$43,1), N24, if($J25>=CEILING(100/'Intermediate Sums'!E$43,1), ($J25-1)*'Intermediate Sums'!$B$26, (CEILING('Intermediate Sums'!E61/'Intermediate Sums'!E$49,1)+$J25-1)*'Intermediate Sums'!$B$26)) -> 225 | O25: =if($J24>=CEILING(100/'Intermediate Sums'!F$43,1), O24, if($J25>=CEILING(100/'Intermediate Sums'!F$43,1), ($J25-1)*'Intermediate Sums'!$B$26, (CEILING('Intermediate Sums'!F61/'Intermediate Sums'!F$49,1)+$J25-1)*'Intermediate Sums'!$B$26)) -> 300 | P25: =if($J24>=CEILING(100/'Intermediate Sums'!G$43,1), P24, if($J25>=CEILING(100/'Intermediate Sums'!G$43,1), ($J25-1)*'Intermediate Sums'!$B$26, (CEILING('Intermediate Sums'!G61/'Intermediate Sums'!G$49,1)+$J25-1)*'Intermediate Sums'!$B$26)) -> 300 | Q25: =if($J24>=CEILING(100/'Intermediate Sums'!H$43,1), Q24, if($J25>=CEILING(100/'Intermediate Sums'!H$43,1), ($J25-1)*'Intermediate Sums'!$B$26, (CEILING('Intermediate Sums'!H61/'Intermediate Sums'!H$49,1)+$J25-1)*'Intermediate Sums'!$B$26)) -> 375
A26: 6 | B26: =K26+0 -> 150 | C26: {=L26+INDEX('Intermediate Sums'!$B$17:$AP$17, MATCH(TRUE, 'Intermediate Sums'!$B$16:$AP$16 > C$19, 0))} -> 166.66667 | D26: {=M26+INDEX('Intermediate Sums'!$B$17:$AP$17, MATCH(TRUE, 'Intermediate Sums'!$B$16:$AP$16 > D$19, 0))} -> 183.33333 | E26: {=N26+INDEX('Intermediate Sums'!$B$17:$AP$17, MATCH(TRUE, 'Intermediate Sums'!$B$16:$AP$16 > E$19, 0))} -> 308.33333 | F26: {=O26+INDEX('Intermediate Sums'!$B$17:$AP$17, MATCH(TRUE, 'Intermediate Sums'!$B$16:$AP$16 > F$19, 0))} -> 416.66667 | G26: {=P26+INDEX('Intermediate Sums'!$B$17:$AP$17, MATCH(TRUE, 'Intermediate Sums'!$B$16:$AP$16 > G$19, 0))} -> 466.66667 | H26: {=Q26+INDEX('Intermediate Sums'!$B$17:$AP$17, MATCH(TRUE, 'Intermediate Sums'!$B$16:$AP$16 > H$19, 0))} -> 575 | J26: 6 | K26: =if($J25>=CEILING(100/'Intermediate Sums'!B$43,1), K25, if($J26>=CEILING(100/'Intermediate Sums'!B$43,1), ($J26-1)*'Intermediate Sums'!$B$26, (CEILING('Intermediate Sums'!B62/'Intermediate Sums'!B$49,1)+$J26-1)*'Intermediate Sums'!$B$26)) -> 150 | L26: =if($J25>=CEILING(100/'Intermediate Sums'!C$43,1), L25, if($J26>=CEILING(100/'Intermediate Sums'!C$43,1), ($J26-1)*'Intermediate Sums'!$B$26, (CEILING('Intermediate Sums'!C62/'Intermediate Sums'!C$49,1)+$J26-1)*'Intermediate Sums'!$B$26)) -> 150 | M26: =if($J25>=CEILING(100/'Intermediate Sums'!D$43,1), M25, if($J26>=CEILING(100/'Intermediate Sums'!D$43,1), ($J26-1)*'Intermediate Sums'!$B$26, (CEILING('Intermediate Sums'!D62/'Intermediate Sums'!D$49,1)+$J26-1)*'Intermediate Sums'!$B$26)) -> 150 | N26: =if($J25>=CEILING(100/'Intermediate Sums'!E$43,1), N25, if($J26>=CEILING(100/'Intermediate Sums'!E$43,1), ($J26-1)*'Intermediate Sums'!$B$26, (CEILING('Intermediate Sums'!E62/'Intermediate Sums'!E$49,1)+$J26-1)*'Intermediate Sums'!$B$26)) -> 225 | O26: =if($J25>=CEILING(100/'Intermediate Sums'!F$43,1), O25, if($J26>=CEILING(100/'Intermediate Sums'!F$43,1), ($J26-1)*'Intermediate Sums'!$B$26, (CEILING('Intermediate Sums'!F62/'Intermediate Sums'!F$49,1)+$J26-1)*'Intermediate Sums'!$B$26)) -> 300 | P26: =if($J25>=CEILING(100/'Intermediate Sums'!G$43,1), P25, if($J26>=CEILING(100/'Intermediate Sums'!G$43,1), ($J26-1)*'Intermediate Sums'!$B$26, (CEILING('Intermediate Sums'!G62/'Intermediate Sums'!G$49,1)+$J26-1)*'Intermediate Sums'!$B$26)) -> 300 | Q26: =if($J25>=CEILING(100/'Intermediate Sums'!H$43,1), Q25, if($J26>=CEILING(100/'Intermediate Sums'!H$43,1), ($J26-1)*'Intermediate Sums'!$B$26, (CEILING('Intermediate Sums'!H62/'Intermediate Sums'!H$49,1)+$J26-1)*'Intermediate Sums'!$B$26)) -> 375
A27: 7 | B27: =K27+0 -> 150 | C27: {=L27+INDEX('Intermediate Sums'!$B$17:$AP$17, MATCH(TRUE, 'Intermediate Sums'!$B$16:$AP$16 > C$19, 0))} -> 166.66667 | D27: {=M27+INDEX('Intermediate Sums'!$B$17:$AP$17, MATCH(TRUE, 'Intermediate Sums'!$B$16:$AP$16 > D$19, 0))} -> 183.33333 | E27: {=N27+INDEX('Intermediate Sums'!$B$17:$AP$17, MATCH(TRUE, 'Intermediate Sums'!$B$16:$AP$16 > E$19, 0))} -> 308.33333 | F27: {=O27+INDEX('Intermediate Sums'!$B$17:$AP$17, MATCH(TRUE, 'Intermediate Sums'!$B$16:$AP$16 > F$19, 0))} -> 416.66667 | G27: {=P27+INDEX('Intermediate Sums'!$B$17:$AP$17, MATCH(TRUE, 'Intermediate Sums'!$B$16:$AP$16 > G$19, 0))} -> 466.66667 | H27: {=Q27+INDEX('Intermediate Sums'!$B$17:$AP$17, MATCH(TRUE, 'Intermediate Sums'!$B$16:$AP$16 > H$19, 0))} -> 575 | J27: 7 | K27: =if($J26>=CEILING(100/'Intermediate Sums'!B$43,1), K26, if($J27>=CEILING(100/'Intermediate Sums'!B$43,1), ($J27-1)*'Intermediate Sums'!$B$26, (CEILING('Intermediate Sums'!B63/'Intermediate Sums'!B$49,1)+$J27-1)*'Intermediate Sums'!$B$26)) -> 150 | L27: =if($J26>=CEILING(100/'Intermediate Sums'!C$43,1), L26, if($J27>=CEILING(100/'Intermediate Sums'!C$43,1), ($J27-1)*'Intermediate Sums'!$B$26, (CEILING('Intermediate Sums'!C63/'Intermediate Sums'!C$49,1)+$J27-1)*'Intermediate Sums'!$B$26)) -> 150 | M27: =if($J26>=CEILING(100/'Intermediate Sums'!D$43,1), M26, if($J27>=CEILING(100/'Intermediate Sums'!D$43,1), ($J27-1)*'Intermediate Sums'!$B$26, (CEILING('Intermediate Sums'!D63/'Intermediate Sums'!D$49,1)+$J27-1)*'Intermediate Sums'!$B$26)) -> 150 | N27: =if($J26>=CEILING(100/'Intermediate Sums'!E$43,1), N26, if($J27>=CEILING(100/'Intermediate Sums'!E$43,1), ($J27-1)*'Intermediate Sums'!$B$26, (CEILING('Intermediate Sums'!E63/'Intermediate Sums'!E$49,1)+$J27-1)*'Intermediate Sums'!$B$26)) -> 225 | O27: =if($J26>=CEILING(100/'Intermediate Sums'!F$43,1), O26, if($J27>=CEILING(100/'Intermediate Sums'!F$43,1), ($J27-1)*'Intermediate Sums'!$B$26, (CEILING('Intermediate Sums'!F63/'Intermediate Sums'!F$49,1)+$J27-1)*'Intermediate Sums'!$B$26)) -> 300 | P27: =if($J26>=CEILING(100/'Intermediate Sums'!G$43,1), P26, if($J27>=CEILING(100/'Intermediate Sums'!G$43,1), ($J27-1)*'Intermediate Sums'!$B$26, (CEILING('Intermediate Sums'!G63/'Intermediate Sums'!G$49,1)+$J27-1)*'Intermediate Sums'!$B$26)) -> 300 | Q27: =if($J26>=CEILING(100/'Intermediate Sums'!H$43,1), Q26, if($J27>=CEILING(100/'Intermediate Sums'!H$43,1), ($J27-1)*'Intermediate Sums'!$B$26, (CEILING('Intermediate Sums'!H63/'Intermediate Sums'!H$49,1)+$J27-1)*'Intermediate Sums'!$B$26)) -> 375
A29: G2 TTK Total | J29: G2 TTK Shots
A30: Num hs vs dist | B30: 0 | C30: 10 | D30: 20 | E30: 35 | F30: 50 | G30: 70 | H30: 80 | J30: Num hs vs dist | K30: 0 | L30: 10 | M30: 20 | N30: 35 | O30: 50 | P30: 70 | Q30: 80
A31: 0 | B31: =K31+0 -> 350.19455 | C31: {=L31+INDEX('Intermediate Sums'!$B$23:$AP$23, MATCH(TRUE, 'Intermediate Sums'!$B$22:$AP$22 > C$30, 0))} -> 350.19455 | D31: {=M31+INDEX('Intermediate Sums'!$B$23:$AP$23, MATCH(TRUE, 'Intermediate Sums'!$B$22:$AP$22 > D$30, 0))} -> 366.86122 | E31: {=N31+INDEX('Intermediate Sums'!$B$23:$AP$23, MATCH(TRUE, 'Intermediate Sums'!$B$22:$AP$22 > E$30, 0))} -> 500.2594 | F31: {=O31+INDEX('Intermediate Sums'!$B$23:$AP$23, MATCH(TRUE, 'Intermediate Sums'!$B$22:$AP$22 > F$30, 0))} -> 500.2594 | G31: {=P31+INDEX('Intermediate Sums'!$B$23:$AP$23, MATCH(TRUE, 'Intermediate Sums'!$B$22:$AP$22 > G$30, 0))} -> 533.59274 | H31: {=Q31+INDEX('Intermediate Sums'!$B$23:$AP$23, MATCH(TRUE, 'Intermediate Sums'!$B$22:$AP$22 > H$30, 0))} -> 650.32425 | J31: 0 | K31: =if($J31>=CEILING(100/'Intermediate Sums'!B$46,1), ($J31-1)*'Intermediate Sums'!$B$27, (CEILING('Intermediate Sums'!B67/'Intermediate Sums'!B$52,1)+$J31-1)*'Intermediate Sums'!$B$27) -> 350.19455 | L31: =if($J31>=CEILING(100/'Intermediate Sums'!C$46,1), ($J31-1)*'Intermediate Sums'!$B$27, (CEILING('Intermediate Sums'!C67/'Intermediate Sums'!C$52,1)+$J31-1)*'Intermediate Sums'!$B$27) -> 350.19455 | M31: =if($J31>=CEILING(100/'Intermediate Sums'!D$46,1), ($J31-1)*'Intermediate Sums'!$B$27, (CEILING('Intermediate Sums'!D67/'Intermediate Sums'!D$52,1)+$J31-1)*'Intermediate Sums'!$B$27) -> 350.19455 | N31: =if($J31>=CEILING(100/'Intermediate Sums'!E$46,1), ($J31-1)*'Intermediate Sums'!$B$27, (CEILING('Intermediate Sums'!E67/'Intermediate Sums'!E$52,1)+$J31-1)*'Intermediate Sums'!$B$27) -> 466.92607 | O31: =if($J31>=CEILING(100/'Intermediate Sums'!F$46,1), ($J31-1)*'Intermediate Sums'!$B$27, (CEILING('Intermediate Sums'!F67/'Intermediate Sums'!F$52,1)+$J31-1)*'Intermediate Sums'!$B$27) -> 466.92607 | P31: =if($J31>=CEILING(100/'Intermediate Sums'!G$46,1), ($J31-1)*'Intermediate Sums'!$B$27, (CEILING('Intermediate Sums'!G67/'Intermediate Sums'!G$52,1)+$J31-1)*'Intermediate Sums'!$B$27) -> 466.92607 | Q31: =if($J31>=CEILING(100/'Intermediate Sums'!H$46,1), ($J31-1)*'Intermediate Sums'!$B$27, (CEILING('Intermediate Sums'!H67/'Intermediate Sums'!H$52,1)+$J31-1)*'Intermediate Sums'!$B$27) -> 583.65759
A32: 1 | B32: =K32+0 -> 350.19455 | C32: {=L32+INDEX('Intermediate Sums'!$B$23:$AP$23, MATCH(TRUE, 'Intermediate Sums'!$B$22:$AP$22 > C$30, 0))} -> 350.19455 | D32: {=M32+INDEX('Intermediate Sums'!$B$23:$AP$23, MATCH(TRUE, 'Intermediate Sums'!$B$22:$AP$22 > D$30, 0))} -> 366.86122 | E32: {=N32+INDEX('Intermediate Sums'!$B$23:$AP$23, MATCH(TRUE, 'Intermediate Sums'!$B$22:$AP$22 > E$30, 0))} -> 500.2594 | F32: {=O32+INDEX('Intermediate Sums'!$B$23:$AP$23, MATCH(TRUE, 'Intermediate Sums'!$B$22:$AP$22 > F$30, 0))} -> 500.2594 | G32: {=P32+INDEX('Intermediate Sums'!$B$23:$AP$23, MATCH(TRUE, 'Intermediate Sums'!$B$22:$AP$22 > G$30, 0))} -> 533.59274 | H32: {=Q32+INDEX('Intermediate Sums'!$B$23:$AP$23, MATCH(TRUE, 'Intermediate Sums'!$B$22:$AP$22 > H$30, 0))} -> 650.32425 | J32: 1 | K32: =if($J31>=CEILING(100/'Intermediate Sums'!B$46,1), K31, if($J32>=CEILING(100/'Intermediate Sums'!B$46,1), ($J32-1)*'Intermediate Sums'!$B$27, (CEILING('Intermediate Sums'!B68/'Intermediate Sums'!B$52,1)+$J32-1)*'Intermediate Sums'!$B$27)) -> 350.19455 | L32: =if($J31>=CEILING(100/'Intermediate Sums'!C$46,1), L31, if($J32>=CEILING(100/'Intermediate Sums'!C$46,1), ($J32-1)*'Intermediate Sums'!$B$27, (CEILING('Intermediate Sums'!C68/'Intermediate Sums'!C$52,1)+$J32-1)*'Intermediate Sums'!$B$27)) -> 350.19455 | M32: =if($J31>=CEILING(100/'Intermediate Sums'!D$46,1), M31, if($J32>=CEILING(100/'Intermediate Sums'!D$46,1), ($J32-1)*'Intermediate Sums'!$B$27, (CEILING('Intermediate Sums'!D68/'Intermediate Sums'!D$52,1)+$J32-1)*'Intermediate Sums'!$B$27)) -> 350.19455 | N32: =if($J31>=CEILING(100/'Intermediate Sums'!E$46,1), N31, if($J32>=CEILING(100/'Intermediate Sums'!E$46,1), ($J32-1)*'Intermediate Sums'!$B$27, (CEILING('Intermediate Sums'!E68/'Intermediate Sums'!E$52,1)+$J32-1)*'Intermediate Sums'!$B$27)) -> 466.92607 | O32: =if($J31>=CEILING(100/'Intermediate Sums'!F$46,1), O31, if($J32>=CEILING(100/'Intermediate Sums'!F$46,1), ($J32-1)*'Intermediate Sums'!$B$27, (CEILING('Intermediate Sums'!F68/'Intermediate Sums'!F$52,1)+$J32-1)*'Intermediate Sums'!$B$27)) -> 466.92607 | P32: =if($J31>=CEILING(100/'Intermediate Sums'!G$46,1), P31, if($J32>=CEILING(100/'Intermediate Sums'!G$46,1), ($J32-1)*'Intermediate Sums'!$B$27, (CEILING('Intermediate Sums'!G68/'Intermediate Sums'!G$52,1)+$J32-1)*'Intermediate Sums'!$B$27)) -> 466.92607 | Q32: =if($J31>=CEILING(100/'Intermediate Sums'!H$46,1), Q31, if($J32>=CEILING(100/'Intermediate Sums'!H$46,1), ($J32-1)*'Intermediate Sums'!$B$27, (CEILING('Intermediate Sums'!H68/'Intermediate Sums'!H$52,1)+$J32-1)*'Intermediate Sums'!$B$27)) -> 583.65759
A33: 2 | B33: =K33+0 -> 350.19455 | C33: {=L33+INDEX('Intermediate Sums'!$B$23:$AP$23, MATCH(TRUE, 'Intermediate Sums'!$B$22:$AP$22 > C$30, 0))} -> 350.19455 | D33: {=M33+INDEX('Intermediate Sums'!$B$23:$AP$23, MATCH(TRUE, 'Intermediate Sums'!$B$22:$AP$22 > D$30, 0))} -> 366.86122 | E33: {=N33+INDEX('Intermediate Sums'!$B$23:$AP$23, MATCH(TRUE, 'Intermediate Sums'!$B$22:$AP$22 > E$30, 0))} -> 500.2594 | F33: {=O33+INDEX('Intermediate Sums'!$B$23:$AP$23, MATCH(TRUE, 'Intermediate Sums'!$B$22:$AP$22 > F$30, 0))} -> 500.2594 | G33: {=P33+INDEX('Intermediate Sums'!$B$23:$AP$23, MATCH(TRUE, 'Intermediate Sums'!$B$22:$AP$22 > G$30, 0))} -> 533.59274 | H33: {=Q33+INDEX('Intermediate Sums'!$B$23:$AP$23, MATCH(TRUE, 'Intermediate Sums'!$B$22:$AP$22 > H$30, 0))} -> 650.32425 | J33: 2 | K33: =if($J32>=CEILING(100/'Intermediate Sums'!B$46,1), K32, if($J33>=CEILING(100/'Intermediate Sums'!B$46,1), ($J33-1)*'Intermediate Sums'!$B$27, (CEILING('Intermediate Sums'!B69/'Intermediate Sums'!B$52,1)+$J33-1)*'Intermediate Sums'!$B$27)) -> 350.19455 | L33: =if($J32>=CEILING(100/'Intermediate Sums'!C$46,1), L32, if($J33>=CEILING(100/'Intermediate Sums'!C$46,1), ($J33-1)*'Intermediate Sums'!$B$27, (CEILING('Intermediate Sums'!C69/'Intermediate Sums'!C$52,1)+$J33-1)*'Intermediate Sums'!$B$27)) -> 350.19455 | M33: =if($J32>=CEILING(100/'Intermediate Sums'!D$46,1), M32, if($J33>=CEILING(100/'Intermediate Sums'!D$46,1), ($J33-1)*'Intermediate Sums'!$B$27, (CEILING('Intermediate Sums'!D69/'Intermediate Sums'!D$52,1)+$J33-1)*'Intermediate Sums'!$B$27)) -> 350.19455 | N33: =if($J32>=CEILING(100/'Intermediate Sums'!E$46,1), N32, if($J33>=CEILING(100/'Intermediate Sums'!E$46,1), ($J33-1)*'Intermediate Sums'!$B$27, (CEILING('Intermediate Sums'!E69/'Intermediate Sums'!E$52,1)+$J33-1)*'Intermediate Sums'!$B$27)) -> 466.92607 | O33: =if($J32>=CEILING(100/'Intermediate Sums'!F$46,1), O32, if($J33>=CEILING(100/'Intermediate Sums'!F$46,1), ($J33-1)*'Intermediate Sums'!$B$27, (CEILING('Intermediate Sums'!F69/'Intermediate Sums'!F$52,1)+$J33-1)*'Intermediate Sums'!$B$27)) -> 466.92607 | P33: =if($J32>=CEILING(100/'Intermediate Sums'!G$46,1), P32, if($J33>=CEILING(100/'Intermediate Sums'!G$46,1), ($J33-1)*'Intermediate Sums'!$B$27, (CEILING('Intermediate Sums'!G69/'Intermediate Sums'!G$52,1)+$J33-1)*'Intermediate Sums'!$B$27)) -> 466.92607 | Q33: =if($J32>=CEILING(100/'Intermediate Sums'!H$46,1), Q32, if($J33>=CEILING(100/'Intermediate Sums'!H$46,1), ($J33-1)*'Intermediate Sums'!$B$27, (CEILING('Intermediate Sums'!H69/'Intermediate Sums'!H$52,1)+$J33-1)*'Intermediate Sums'!$B$27)) -> 583.65759
A34: 3 | B34: =K34+0 -> 233.46303 | C34: {=L34+INDEX('Intermediate Sums'!$B$23:$AP$23, MATCH(TRUE, 'Intermediate Sums'!$B$22:$AP$22 > C$30, 0))} -> 233.46303 | D34: {=M34+INDEX('Intermediate Sums'!$B$23:$AP$23, MATCH(TRUE, 'Intermediate Sums'!$B$22:$AP$22 > D$30, 0))} -> 250.1297 | E34: {=N34+INDEX('Intermediate Sums'!$B$23:$AP$23, MATCH(TRUE, 'Intermediate Sums'!$B$22:$AP$22 > E$30, 0))} -> 383.52789 | F34: {=O34+INDEX('Intermediate Sums'!$B$23:$AP$23, MATCH(TRUE, 'Intermediate Sums'!$B$22:$AP$22 > F$30, 0))} -> 383.52789 | G34: {=P34+INDEX('Intermediate Sums'!$B$23:$AP$23, MATCH(TRUE, 'Intermediate Sums'!$B$22:$AP$22 > G$30, 0))} -> 416.86122 | H34: {=Q34+INDEX('Intermediate Sums'!$B$23:$AP$23, MATCH(TRUE, 'Intermediate Sums'!$B$22:$AP$22 > H$30, 0))} -> 533.59274 | J34: 3 | K34: =if($J33>=CEILING(100/'Intermediate Sums'!B$46,1), K33, if($J34>=CEILING(100/'Intermediate Sums'!B$46,1), ($J34-1)*'Intermediate Sums'!$B$27, (CEILING('Intermediate Sums'!B70/'Intermediate Sums'!B$52,1)+$J34-1)*'Intermediate Sums'!$B$27)) -> 233.46303 | L34: =if($J33>=CEILING(100/'Intermediate Sums'!C$46,1), L33, if($J34>=CEILING(100/'Intermediate Sums'!C$46,1), ($J34-1)*'Intermediate Sums'!$B$27, (CEILING('Intermediate Sums'!C70/'Intermediate Sums'!C$52,1)+$J34-1)*'Intermediate Sums'!$B$27)) -> 233.46303 | M34: =if($J33>=CEILING(100/'Intermediate Sums'!D$46,1), M33, if($J34>=CEILING(100/'Intermediate Sums'!D$46,1), ($J34-1)*'Intermediate Sums'!$B$27, (CEILING('Intermediate Sums'!D70/'Intermediate Sums'!D$52,1)+$J34-1)*'Intermediate Sums'!$B$27)) -> 233.46303 | N34: =if($J33>=CEILING(100/'Intermediate Sums'!E$46,1), N33, if($J34>=CEILING(100/'Intermediate Sums'!E$46,1), ($J34-1)*'Intermediate Sums'!$B$27, (CEILING('Intermediate Sums'!E70/'Intermediate Sums'!E$52,1)+$J34-1)*'Intermediate Sums'!$B$27)) -> 350.19455 | O34: =if($J33>=CEILING(100/'Intermediate Sums'!F$46,1), O33, if($J34>=CEILING(100/'Intermediate Sums'!F$46,1), ($J34-1)*'Intermediate Sums'!$B$27, (CEILING('Intermediate Sums'!F70/'Intermediate Sums'!F$52,1)+$J34-1)*'Intermediate Sums'!$B$27)) -> 350.19455 | P34: =if($J33>=CEILING(100/'Intermediate Sums'!G$46,1), P33, if($J34>=CEILING(100/'Intermediate Sums'!G$46,1), ($J34-1)*'Intermediate Sums'!$B$27, (CEILING('Intermediate Sums'!G70/'Intermediate Sums'!G$52,1)+$J34-1)*'Intermediate Sums'!$B$27)) -> 350.19455 | Q34: =if($J33>=CEILING(100/'Intermediate Sums'!H$46,1), Q33, if($J34>=CEILING(100/'Intermediate Sums'!H$46,1), ($J34-1)*'Intermediate Sums'!$B$27, (CEILING('Intermediate Sums'!H70/'Intermediate Sums'!H$52,1)+$J34-1)*'Intermediate Sums'!$B$27)) -> 466.92607
A35: 4 | B35: =K35+0 -> 233.46303 | C35: {=L35+INDEX('Intermediate Sums'!$B$23:$AP$23, MATCH(TRUE, 'Intermediate Sums'!$B$22:$AP$22 > C$30, 0))} -> 233.46303 | D35: {=M35+INDEX('Intermediate Sums'!$B$23:$AP$23, MATCH(TRUE, 'Intermediate Sums'!$B$22:$AP$22 > D$30, 0))} -> 250.1297 | E35: {=N35+INDEX('Intermediate Sums'!$B$23:$AP$23, MATCH(TRUE, 'Intermediate Sums'!$B$22:$AP$22 > E$30, 0))} -> 383.52789 | F35: {=O35+INDEX('Intermediate Sums'!$B$23:$AP$23, MATCH(TRUE, 'Intermediate Sums'!$B$22:$AP$22 > F$30, 0))} -> 383.52789 | G35: {=P35+INDEX('Intermediate Sums'!$B$23:$AP$23, MATCH(TRUE, 'Intermediate Sums'!$B$22:$AP$22 > G$30, 0))} -> 416.86122 | H35: {=Q35+INDEX('Intermediate Sums'!$B$23:$AP$23, MATCH(TRUE, 'Intermediate Sums'!$B$22:$AP$22 > H$30, 0))} -> 533.59274 | J35: 4 | K35: =if($J34>=CEILING(100/'Intermediate Sums'!B$46,1), K34, if($J35>=CEILING(100/'Intermediate Sums'!B$46,1), ($J35-1)*'Intermediate Sums'!$B$27, (CEILING('Intermediate Sums'!B71/'Intermediate Sums'!B$52,1)+$J35-1)*'Intermediate Sums'!$B$27)) -> 233.46303 | L35: =if($J34>=CEILING(100/'Intermediate Sums'!C$46,1), L34, if($J35>=CEILING(100/'Intermediate Sums'!C$46,1), ($J35-1)*'Intermediate Sums'!$B$27, (CEILING('Intermediate Sums'!C71/'Intermediate Sums'!C$52,1)+$J35-1)*'Intermediate Sums'!$B$27)) -> 233.46303 | M35: =if($J34>=CEILING(100/'Intermediate Sums'!D$46,1), M34, if($J35>=CEILING(100/'Intermediate Sums'!D$46,1), ($J35-1)*'Intermediate Sums'!$B$27, (CEILING('Intermediate Sums'!D71/'Intermediate Sums'!D$52,1)+$J35-1)*'Intermediate Sums'!$B$27)) -> 233.46303 | N35: =if($J34>=CEILING(100/'Intermediate Sums'!E$46,1), N34, if($J35>=CEILING(100/'Intermediate Sums'!E$46,1), ($J35-1)*'Intermediate Sums'!$B$27, (CEILING('Intermediate Sums'!E71/'Intermediate Sums'!E$52,1)+$J35-1)*'Intermediate Sums'!$B$27)) -> 350.19455 | O35: =if($J34>=CEILING(100/'Intermediate Sums'!F$46,1), O34, if($J35>=CEILING(100/'Intermediate Sums'!F$46,1), ($J35-1)*'Intermediate Sums'!$B$27, (CEILING('Intermediate Sums'!F71/'Intermediate Sums'!F$52,1)+$J35-1)*'Intermediate Sums'!$B$27)) -> 350.19455 | P35: =if($J34>=CEILING(100/'Intermediate Sums'!G$46,1), P34, if($J35>=CEILING(100/'Intermediate Sums'!G$46,1), ($J35-1)*'Intermediate Sums'!$B$27, (CEILING('Intermediate Sums'!G71/'Intermediate Sums'!G$52,1)+$J35-1)*'Intermediate Sums'!$B$27)) -> 350.19455 | Q35: =if($J34>=CEILING(100/'Intermediate Sums'!H$46,1), Q34, if($J35>=CEILING(100/'Intermediate Sums'!H$46,1), ($J35-1)*'Intermediate Sums'!$B$27, (CEILING('Intermediate Sums'!H71/'Intermediate Sums'!H$52,1)+$J35-1)*'Intermediate Sums'!$B$27)) -> 466.92607 | X35: =Data!X8 | Y35: =Data!Y8 | Z35: =Data!Z8 | AA35: =Data!AA8 | AB35: =Data!AB8 | AC35: =Data!AC8 | AD35: =Data!AD8 | AE35: =Data!AE8 | ... AH35: =Data!AH8
A36: 5 | B36: =K36+0 -> 233.46303 | C36: {=L36+INDEX('Intermediate Sums'!$B$23:$AP$23, MATCH(TRUE, 'Intermediate Sums'!$B$22:$AP$22 > C$30, 0))} -> 233.46303 | D36: {=M36+INDEX('Intermediate Sums'!$B$23:$AP$23, MATCH(TRUE, 'Intermediate Sums'!$B$22:$AP$22 > D$30, 0))} -> 250.1297 | E36: {=N36+INDEX('Intermediate Sums'!$B$23:$AP$23, MATCH(TRUE, 'Intermediate Sums'!$B$22:$AP$22 > E$30, 0))} -> 383.52789 | F36: {=O36+INDEX('Intermediate Sums'!$B$23:$AP$23, MATCH(TRUE, 'Intermediate Sums'!$B$22:$AP$22 > F$30, 0))} -> 383.52789 | G36: {=P36+INDEX('Intermediate Sums'!$B$23:$AP$23, MATCH(TRUE, 'Intermediate Sums'!$B$22:$AP$22 > G$30, 0))} -> 416.86122 | H36: {=Q36+INDEX('Intermediate Sums'!$B$23:$AP$23, MATCH(TRUE, 'Intermediate Sums'!$B$22:$AP$22 > H$30, 0))} -> 533.59274 | J36: 5 | K36: =if($J35>=CEILING(100/'Intermediate Sums'!B$46,1), K35, if($J36>=CEILING(100/'Intermediate Sums'!B$46,1), ($J36-1)*'Intermediate Sums'!$B$27, (CEILING('Intermediate Sums'!B72/'Intermediate Sums'!B$52,1)+$J36-1)*'Intermediate Sums'!$B$27)) -> 233.46303 | L36: =if($J35>=CEILING(100/'Intermediate Sums'!C$46,1), L35, if($J36>=CEILING(100/'Intermediate Sums'!C$46,1), ($J36-1)*'Intermediate Sums'!$B$27, (CEILING('Intermediate Sums'!C72/'Intermediate Sums'!C$52,1)+$J36-1)*'Intermediate Sums'!$B$27)) -> 233.46303 | M36: =if($J35>=CEILING(100/'Intermediate Sums'!D$46,1), M35, if($J36>=CEILING(100/'Intermediate Sums'!D$46,1), ($J36-1)*'Intermediate Sums'!$B$27, (CEILING('Intermediate Sums'!D72/'Intermediate Sums'!D$52,1)+$J36-1)*'Intermediate Sums'!$B$27)) -> 233.46303 | N36: =if($J35>=CEILING(100/'Intermediate Sums'!E$46,1), N35, if($J36>=CEILING(100/'Intermediate Sums'!E$46,1), ($J36-1)*'Intermediate Sums'!$B$27, (CEILING('Intermediate Sums'!E72/'Intermediate Sums'!E$52,1)+$J36-1)*'Intermediate Sums'!$B$27)) -> 350.19455 | O36: =if($J35>=CEILING(100/'Intermediate Sums'!F$46,1), O35, if($J36>=CEILING(100/'Intermediate Sums'!F$46,1), ($J36-1)*'Intermediate Sums'!$B$27, (CEILING('Intermediate Sums'!F72/'Intermediate Sums'!F$52,1)+$J36-1)*'Intermediate Sums'!$B$27)) -> 350.19455 | P36: =if($J35>=CEILING(100/'Intermediate Sums'!G$46,1), P35, if($J36>=CEILING(100/'Intermediate Sums'!G$46,1), ($J36-1)*'Intermediate Sums'!$B$27, (CEILING('Intermediate Sums'!G72/'Intermediate Sums'!G$52,1)+$J36-1)*'Intermediate Sums'!$B$27)) -> 350.19455 | Q36: =if($J35>=CEILING(100/'Intermediate Sums'!H$46,1), Q35, if($J36>=CEILING(100/'Intermediate Sums'!H$46,1), ($J36-1)*'Intermediate Sums'!$B$27, (CEILING('Intermediate Sums'!H72/'Intermediate Sums'!H$52,1)+$J36-1)*'Intermediate Sums'!$B$27)) -> 466.92607
A37: 6 | B37: =K37+0 -> 233.46303 | C37: {=L37+INDEX('Intermediate Sums'!$B$23:$AP$23, MATCH(TRUE, 'Intermediate Sums'!$B$22:$AP$22 > C$30, 0))} -> 233.46303 | D37: {=M37+INDEX('Intermediate Sums'!$B$23:$AP$23, MATCH(TRUE, 'Intermediate Sums'!$B$22:$AP$22 > D$30, 0))} -> 250.1297 | E37: {=N37+INDEX('Intermediate Sums'!$B$23:$AP$23, MATCH(TRUE, 'Intermediate Sums'!$B$22:$AP$22 > E$30, 0))} -> 383.52789 | F37: {=O37+INDEX('Intermediate Sums'!$B$23:$AP$23, MATCH(TRUE, 'Intermediate Sums'!$B$22:$AP$22 > F$30, 0))} -> 383.52789 | G37: {=P37+INDEX('Intermediate Sums'!$B$23:$AP$23, MATCH(TRUE, 'Intermediate Sums'!$B$22:$AP$22 > G$30, 0))} -> 416.86122 | H37: {=Q37+INDEX('Intermediate Sums'!$B$23:$AP$23, MATCH(TRUE, 'Intermediate Sums'!$B$22:$AP$22 > H$30, 0))} -> 533.59274 | J37: 6 | K37: =if($J36>=CEILING(100/'Intermediate Sums'!B$46,1), K36, if($J37>=CEILING(100/'Intermediate Sums'!B$46,1), ($J37-1)*'Intermediate Sums'!$B$27, (CEILING('Intermediate Sums'!B73/'Intermediate Sums'!B$52,1)+$J37-1)*'Intermediate Sums'!$B$27)) -> 233.46303 | L37: =if($J36>=CEILING(100/'Intermediate Sums'!C$46,1), L36, if($J37>=CEILING(100/'Intermediate Sums'!C$46,1), ($J37-1)*'Intermediate Sums'!$B$27, (CEILING('Intermediate Sums'!C73/'Intermediate Sums'!C$52,1)+$J37-1)*'Intermediate Sums'!$B$27)) -> 233.46303 | M37: =if($J36>=CEILING(100/'Intermediate Sums'!D$46,1), M36, if($J37>=CEILING(100/'Intermediate Sums'!D$46,1), ($J37-1)*'Intermediate Sums'!$B$27, (CEILING('Intermediate Sums'!D73/'Intermediate Sums'!D$52,1)+$J37-1)*'Intermediate Sums'!$B$27)) -> 233.46303 | N37: =if($J36>=CEILING(100/'Intermediate Sums'!E$46,1), N36, if($J37>=CEILING(100/'Intermediate Sums'!E$46,1), ($J37-1)*'Intermediate Sums'!$B$27, (CEILING('Intermediate Sums'!E73/'Intermediate Sums'!E$52,1)+$J37-1)*'Intermediate Sums'!$B$27)) -> 350.19455 | O37: =if($J36>=CEILING(100/'Intermediate Sums'!F$46,1), O36, if($J37>=CEILING(100/'Intermediate Sums'!F$46,1), ($J37-1)*'Intermediate Sums'!$B$27, (CEILING('Intermediate Sums'!F73/'Intermediate Sums'!F$52,1)+$J37-1)*'Intermediate Sums'!$B$27)) -> 350.19455 | P37: =if($J36>=CEILING(100/'Intermediate Sums'!G$46,1), P36, if($J37>=CEILING(100/'Intermediate Sums'!G$46,1), ($J37-1)*'Intermediate Sums'!$B$27, (CEILING('Intermediate Sums'!G73/'Intermediate Sums'!G$52,1)+$J37-1)*'Intermediate Sums'!$B$27)) -> 350.19455 | Q37: =if($J36>=CEILING(100/'Intermediate Sums'!H$46,1), Q36, if($J37>=CEILING(100/'Intermediate Sums'!H$46,1), ($J37-1)*'Intermediate Sums'!$B$27, (CEILING('Intermediate Sums'!H73/'Intermediate Sums'!H$52,1)+$J37-1)*'Intermediate Sums'!$B$27)) -> 466.92607
A38: 7 | B38: =K38+0 -> 233.46303 | C38: {=L38+INDEX('Intermediate Sums'!$B$23:$AP$23, MATCH(TRUE, 'Intermediate Sums'!$B$22:$AP$22 > C$30, 0))} -> 233.46303 | D38: {=M38+INDEX('Intermediate Sums'!$B$23:$AP$23, MATCH(TRUE, 'Intermediate Sums'!$B$22:$AP$22 > D$30, 0))} -> 250.1297 | E38: {=N38+INDEX('Intermediate Sums'!$B$23:$AP$23, MATCH(TRUE, 'Intermediate Sums'!$B$22:$AP$22 > E$30, 0))} -> 383.52789 | F38: {=O38+INDEX('Intermediate Sums'!$B$23:$AP$23, MATCH(TRUE, 'Intermediate Sums'!$B$22:$AP$22 > F$30, 0))} -> 383.52789 | G38: {=P38+INDEX('Intermediate Sums'!$B$23:$AP$23, MATCH(TRUE, 'Intermediate Sums'!$B$22:$AP$22 > G$30, 0))} -> 416.86122 | H38: {=Q38+INDEX('Intermediate Sums'!$B$23:$AP$23, MATCH(TRUE, 'Intermediate Sums'!$B$22:$AP$22 > H$30, 0))} -> 533.59274 | J38: 7 | K38: =if($J37>=CEILING(100/'Intermediate Sums'!B$46,1), K37, if($J38>=CEILING(100/'Intermediate Sums'!B$46,1), ($J38-1)*'Intermediate Sums'!$B$27, (CEILING('Intermediate Sums'!B74/'Intermediate Sums'!B$52,1)+$J38-1)*'Intermediate Sums'!$B$27)) -> 233.46303 | L38: =if($J37>=CEILING(100/'Intermediate Sums'!C$46,1), L37, if($J38>=CEILING(100/'Intermediate Sums'!C$46,1), ($J38-1)*'Intermediate Sums'!$B$27, (CEILING('Intermediate Sums'!C74/'Intermediate Sums'!C$52,1)+$J38-1)*'Intermediate Sums'!$B$27)) -> 233.46303 | M38: =if($J37>=CEILING(100/'Intermediate Sums'!D$46,1), M37, if($J38>=CEILING(100/'Intermediate Sums'!D$46,1), ($J38-1)*'Intermediate Sums'!$B$27, (CEILING('Intermediate Sums'!D74/'Intermediate Sums'!D$52,1)+$J38-1)*'Intermediate Sums'!$B$27)) -> 233.46303 | N38: =if($J37>=CEILING(100/'Intermediate Sums'!E$46,1), N37, if($J38>=CEILING(100/'Intermediate Sums'!E$46,1), ($J38-1)*'Intermediate Sums'!$B$27, (CEILING('Intermediate Sums'!E74/'Intermediate Sums'!E$52,1)+$J38-1)*'Intermediate Sums'!$B$27)) -> 350.19455 | O38: =if($J37>=CEILING(100/'Intermediate Sums'!F$46,1), O37, if($J38>=CEILING(100/'Intermediate Sums'!F$46,1), ($J38-1)*'Intermediate Sums'!$B$27, (CEILING('Intermediate Sums'!F74/'Intermediate Sums'!F$52,1)+$J38-1)*'Intermediate Sums'!$B$27)) -> 350.19455 | P38: =if($J37>=CEILING(100/'Intermediate Sums'!G$46,1), P37, if($J38>=CEILING(100/'Intermediate Sums'!G$46,1), ($J38-1)*'Intermediate Sums'!$B$27, (CEILING('Intermediate Sums'!G74/'Intermediate Sums'!G$52,1)+$J38-1)*'Intermediate Sums'!$B$27)) -> 350.19455 | Q38: =if($J37>=CEILING(100/'Intermediate Sums'!H$46,1), Q37, if($J38>=CEILING(100/'Intermediate Sums'!H$46,1), ($J38-1)*'Intermediate Sums'!$B$27, (CEILING('Intermediate Sums'!H74/'Intermediate Sums'!H$52,1)+$J38-1)*'Intermediate Sums'!$B$27)) -> 466.92607

Sheet Intermediate Sums
A1: Gun 1 | B1: =Data!B1 -> MV | C1: =Data!C1 -> Drag | D1: =Data!D1 -> D Bonus | E1: =Data!E1 -> E Bonus | F1: =Data!F1 -> S Malus | G1: =Data!G1 -> RoF | H1: =Data!H1 -> HS Mult | I1: =Data!I1 -> 0 | ... W1: =Data!W1
B2: =VLOOKUP(Main!$A$2, Data!$A:$Q, 2, false) -> 428 | C2: =VLOOKUP(Main!$A$2, Data!$A:$Q, 3, false) -> 0.0025 | D2: =VLOOKUP(Main!$A$2, Data!$A:$Q, 4, false) -> 0.04 | E2: =VLOOKUP(Main!$A$2, Data!$A:$Q, 5, false) -> 1.25 | F2: =VLOOKUP(Main!$A$2, Data!$A:$Q, 6, false) -> 0.8 | G2: =VLOOKUP(Main!$A$2, Data!$A:$Q, 7, false) -> 800 | H2: =VLOOKUP(Main!$A$2, Data!$A:$Q, 8, false) -> 1.34 | I2: =VLOOKUP(Main!$A$2, Data!$A:$Q, 9, false) -> 33.4 | J2: =VLOOKUP(Main!$A$2, Data!$A:$Q, 10, false) -> 25 | K2: =VLOOKUP(Main!$A$2, Data!$A:$Q, 11, false) -> 25 | L2: =VLOOKUP(Main!$A$2, Data!$A:$Q, 12, false) -> 20 | M2: =VLOOKUP(Main!$A$2, Data!$A:$Q, 13, false) -> 16.7 | N2: =VLOOKUP(Main!$A$2, Data!$A:$Q, 14, false) -> 16.7 | O2: =VLOOKUP(Main!$A$2, Data!$A:$Q, 15, false) -> 14.3
B3: =Define!B5 -> H Bonus | C3: =Define!C5 -> D Bonus
B4: =VLOOKUP(Main!$B$2, Define!A6:C9, 2, false) -> 0 | C4: =VLOOKUP(Main!$B$2, Define!A6:C9, 3, false) -> 1
B5: =Define!B11 -> V Mod
B6: =VLOOKUP(Main!$C$2, Define!A12:B14, 2, false) -> 1
A8: Gun 2 | B8: =Data!B1 -> MV | C8: =Data!C1 -> Drag | D8: =Data!D1 -> D Bonus | E8: =Data!E1 -> E Bonus | F8: =Data!F1 -> S Malus | G8: =Data!G1 -> RoF | H8: =Data!H1 -> HS Mult | I8: =Data!I1 -> 0 | ... O8: =Data!O1 -> 80 | P8: =Data!P8 | Q8: =Data!Q8 | R8: =Data!R8 | S8: =Data!S8 | T8: =Data!T8 | U8: =Data!U8 | V8: =Data!V8 | W8: =Data!W8
B9: =VLOOKUP(Main!$A$5, Data!$A:$Q, 2, false) -> 840 | C9: =VLOOKUP(Main!$A$5, Data!$A:$Q, 3, false) -> 0.0025 | D9: =VLOOKUP(Main!$A$5, Data!$A:$Q, 4, false) -> 0.04 | E9: =VLOOKUP(Main!$A$5, Data!$A:$Q, 5, false) -> 1.25 | F9: =VLOOKUP(Main!$A$5, Data!$A:$Q, 6, false) -> 0.8 | G9: =VLOOKUP(Main!$A$5, Data!$A:$Q, 7, false) -> 514 | H9: =VLOOKUP(Main!$A$5, Data!$A:$Q, 8, false) -> 1.34 | I9: =VLOOKUP(Main!$A$5, Data!$A:$Q, 9, false) -> 25 | J9: =VLOOKUP(Main!$A$5, Data!$A:$Q, 10, false) -> 25 | K9: =VLOOKUP(Main!$A$5, Data!$A:$Q, 11, false) -> 25 | L9: =VLOOKUP(Main!$A$5, Data!$A:$Q, 12, false) -> 20 | M9: =VLOOKUP(Main!$A$5, Data!$A:$Q, 13, false) -> 20 | N9: =VLOOKUP(Main!$A$5, Data!$A:$Q, 14, false) -> 20 | O9: =VLOOKUP(Main!$A$5, Data!$A:$Q, 15, false) -> 16.7
B10: =Define!B5 -> H Bonus | C10: =Define!C5 -> D Bonus
B11: =VLOOKUP(Main!$B$5, Define!$A$6:$C$9, 2, false) -> 0 | C11: =VLOOKUP(Main!$B$5, Define!$A$6:$C$9, 3, false) -> 1
B12: =Define!B11 -> V Mod
B13: =VLOOKUP(Main!$C$5, Define!A12:B14, 2, false) -> 1.25
A14: Tick Number | B14: 0 | C14: 1 | D14: 2 | E14: 3 | F14: 4 | G14: 5 | H14: 6 | I14: 7 | J14: 8 | K14: 9 | L14: 10 | M14: 11 | N14: 12 | O14: 13 | P14: 14 | Q14: 15 | R14: 16 | S14: 17 | T14: 18 | U14: 19 | V14: 20 | W14: 21 | X14: 22 | Y14: 23 | Z14: 24 | AA14: 25 | AB14: 26 | AC14: 27 | AD14: 28 | AE14: 29 | AF14: 30 | AG14: 31 | AH14: 32 | AI14: 33 | AJ14: 34 | AK14: 35 | AL14: 36 | AM14: 37 | AN14: 38 | AO14: 39 | AP14: 40
A15: Meters in tick | B15: =(B18/1000)*Define!$B$2 -> 7.1333333 | C15: =(C18/1000)*Define!$B$2 -> 7.0061222 | D15: =(D18/1000)*Define!$B$2 -> 6.8834079 | E15: =(E18/1000)*Define!$B$2 -> 6.7649546 | F15: =(F18/1000)*Define!$B$2 -> 6.6505431 | G15: =(G18/1000)*Define!$B$2 -> 6.5399688 | H15: =(H18/1000)*Define!$B$2 -> 6.4330408 | I15: =(I18/1000)*Define!$B$2 -> 6.3295807 | ... AP15: =(AP18/1000)*Define!$B$2 -> 4.1398136
A16: =CONCATENATE(Main!A2, " (meters)") -> SCW-10 (meters) | B16: =B15 -> 7.1333333 | C16: =B16+C15 -> 14.139456 | D16: =C16+D15 -> 21.022863 | E16: =D16+E15 -> 27.787818 | F16: =E16+F15 -> 34.438361 | G16: =F16+G15 -> 40.97833 | H16: =G16+H15 -> 47.411371 | I16: =H16+I15 -> 53.740951 | J16: =I16+J15 -> 59.970373 | ... AP16: =AO16+AP15 -> 220.27988
A17: Time (ms) | B17: =(B14)*Define!$B$2 -> 0 | C17: =(C14)*Define!$B$2 -> 16.666667 | D17: =(D14)*Define!$B$2 -> 33.333333 | E17: =(E14)*Define!$B$2 -> 50 | F17: =(F14)*Define!$B$2 -> 66.666667 | G17: =(G14)*Define!$B$2 -> 83.333333 | H17: =(H14)*Define!$B$2 -> 100 | I17: =(I14)*Define!$B$2 -> 116.66667 | ... AP17: =(AP14)*Define!$B$2 -> 666.66667
A18: Speed in tick | B18: ='Intermediate Sums'!$B$2*'Intermediate Sums'!$B$6 -> 428 | C18: =B18-(((B18^2)*'Intermediate Sums'!$C$2*'Intermediate Sums'!$C$4)/1000)*Define!$B$2 -> 420.36733 | D18: =C18-(((C18^2)*'Intermediate Sums'!$C$2*'Intermediate Sums'!$C$4)/1000)*Define!$B$2 -> 413.00447 | E18: =D18-(((D18^2)*'Intermediate Sums'!$C$2*'Intermediate Sums'!$C$4)/1000)*Define!$B$2 -> 405.89728 | F18: =E18-(((E18^2)*'Intermediate Sums'!$C$2*'Intermediate Sums'!$C$4)/1000)*Define!$B$2 -> 399.03258 | G18: =F18-(((F18^2)*'Intermediate Sums'!$C$2*'Intermediate Sums'!$C$4)/1000)*Define!$B$2 -> 392.39813 | H18: =G18-(((G18^2)*'Intermediate Sums'!$C$2*'Intermediate Sums'!$C$4)/1000)*Define!$B$2 -> 385.98245 | I18: =H18-(((H18^2)*'Intermediate Sums'!$C$2*'Intermediate Sums'!$C$4)/1000)*Define!$B$2 -> 379.77484 | J18: =I18-(((I18^2)*'Intermediate Sums'!$C$2*'Intermediate Sums'!$C$4)/1000)*Define!$B$2 -> 373.76531 | ... AP18: =AO18-(((AO18^2)*'Intermediate Sums'!$C$2*'Intermediate Sums'!$C$4)/1000)*Define!$B$2 -> 248.38882
A20: Tick Number | B20: 0 | C20: 1 | D20: 2 | E20: 3 | F20: 4 | G20: 5 | H20: 6 | I20: 7 | J20: 8 | K20: 9 | L20: 10 | M20: 11 | N20: 12 | O20: 13 | P20: 14 | Q20: 15 | R20: 16 | S20: 17 | T20: 18 | U20: 19 | V20: 20 | W20: 21 | X20: 22 | Y20: 23 | Z20: 24 | AA20: 25 | AB20: 26 | AC20: 27 | AD20: 28 | AE20: 29 | AF20: 30 | AG20: 31 | AH20: 32 | AI20: 33 | AJ20: 34 | AK20: 35 | AL20: 36 | AM20: 37 | AN20: 38 | AO20: 39 | AP20: 40
A21: Meters in tick | B21: =(B24/1000)*Define!$B$2 -> 17.5 | C21: =(C24/1000)*Define!$B$2 -> 16.734375 | D21: =(D24/1000)*Define!$B$2 -> 16.034277 | E21: =(E24/1000)*Define!$B$2 -> 15.391532 | F21: =(F24/1000)*Define!$B$2 -> 14.799284 | G21: =(G24/1000)*Define!$B$2 -> 14.251737 | H21: =(H24/1000)*Define!$B$2 -> 13.743957 | I21: =(I24/1000)*Define!$B$2 -> 13.271716 | ... AP21: =(AP24/1000)*Define!$B$2 -> 6.2597972
A22: =CONCATENATE(Main!A5, " (meters)") -> KTS100 MK8 (meters) | B22: =B21 -> 17.5 | C22: =B22+C21 -> 34.234375 | D22: =C22+D21 -> 50.268652 | E22: =D22+E21 -> 65.660183 | F22: =E22+F21 -> 80.459467 | G22: =F22+G21 -> 94.711203 | H22: =G22+H21 -> 108.45516 | I22: =H22+I21 -> 121.72688 | J22: =I22+J21 -> 134.55825 | ... AP22: =AO22+AP21 -> 411.74498
A23: Time (ms) | B23: =(B20)*Define!$B$2 -> 0 | C23: =(C20)*Define!$B$2 -> 16.666667 | D23: =(D20)*Define!$B$2 -> 33.333333 | E23: =(E20)*Define!$B$2 -> 50 | F23: =(F20)*Define!$B$2 -> 66.666667 | G23: =(G20)*Define!$B$2 -> 83.333333 | H23: =(H20)*Define!$B$2 -> 100 | I23: =(I20)*Define!$B$2 -> 116.66667 | ... AP23: =(AP20)*Define!$B$2 -> 666.66667
A24: Speed in tick | B24: ='Intermediate Sums'!$B$9*'Intermediate Sums'!$B$13 -> 1050 | C24: =B24-(((B24^2)*'Intermediate Sums'!$C$9*'Intermediate Sums'!$C$11)/1000)*Define!$B$2 -> 1004.0625 | D24: =C24-(((C24^2)*'Intermediate Sums'!$C$9*'Intermediate Sums'!$C$11)/1000)*Define!$B$2 -> 962.0566 | E24: =D24-(((D24^2)*'Intermediate Sums'!$C$9*'Intermediate Sums'!$C$11)/1000)*Define!$B$2 -> 923.4919 | F24: =E24-(((E24^2)*'Intermediate Sums'!$C$9*'Intermediate Sums'!$C$11)/1000)*Define!$B$2 -> 887.95701 | G24: =F24-(((F24^2)*'Intermediate Sums'!$C$9*'Intermediate Sums'!$C$11)/1000)*Define!$B$2 -> 855.10419 | H24: =G24-(((G24^2)*'Intermediate Sums'!$C$9*'Intermediate Sums'!$C$11)/1000)*Define!$B$2 -> 824.63739 | I24: =H24-(((H24^2)*'Intermediate Sums'!$C$9*'Intermediate Sums'!$C$11)/1000)*Define!$B$2 -> 796.30294 | J24: =I24-(((I24^2)*'Intermediate Sums'!$C$9*'Intermediate Sums'!$C$11)/1000)*Define!$B$2 -> 769.88218 | ... AP24: =AO24-(((AO24^2)*'Intermediate Sums'!$C$9*'Intermediate Sums'!$C$11)/1000)*Define!$B$2 -> 375.58783
A26: Gun 1 ms/shot | B26: =60000/'Intermediate Sums'!G2 -> 75
A27: Gun 2 ms/shot | B27: =60000/'Intermediate Sums'!G9 -> 116.73152
A29: Gun 1 BHTK | B29: 0 | C29: 10 | D29: 20 | E29: 35 | F29: 50 | G29: 70 | H29: 80
B30: =CEILING(100/'Intermediate Sums'!I$2,1) -> 3
B31: =(B30-1)*60000/'Intermediate Sums'!G2 -> 150
A32: Gun 2 BHTK | B32: 0 | C32: 10 | D32: 20 | E32: 35 | F32: 50 | G32: 70 | H32: 80
B33: =CEILING(100/(HLOOKUP(B$32,'Intermediate Sums'!$I$8:$O$9,2,true)*('Intermediate Sums'!$H$9+'Intermediate Sums'!$B$11)),1) -> 3
B34: =(B33-1)*60000/'Intermediate Sums'!G9 -> 233.46303
A36: Gun 1 HHTK | B36: =CEILING(100/B43,1) -> 3 | C36: =CEILING(100/C43,1) -> 3 | D36: =CEILING(100/D43,1) -> 3 | E36: =CEILING(100/E43,1) -> 4 | F36: =CEILING(100/F43,1) -> 5 | G36: =CEILING(100/G43,1) -> 5 | H36: =CEILING(100/H43,1) -> 6
A37: Gun 1 HTTK | B37: =(B36-1)*60000/'Intermediate Sums'!$G2 -> 150 | C37: =(C36-1)*60000/'Intermediate Sums'!$G2 -> 150 | D37: =(D36-1)*60000/'Intermediate Sums'!$G2 -> 150 | E37: =(E36-1)*60000/'Intermediate Sums'!$G2 -> 225 | F37: =(F36-1)*60000/'Intermediate Sums'!$G2 -> 300 | G37: =(G36-1)*60000/'Intermediate Sums'!$G2 -> 300 | H37: =(H36-1)*60000/'Intermediate Sums'!$G2 -> 375
A39: Gun 2 HHTK | B39: =CEILING(100/B46,1) -> 3 | C39: =CEILING(100/C46,1) -> 3 | D39: =CEILING(100/D46,1) -> 3 | E39: =CEILING(100/E46,1) -> 4 | F39: =CEILING(100/F46,1) -> 4 | G39: =CEILING(100/G46,1) -> 4 | H39: =CEILING(100/H46,1) -> 5
A40: Gun 2 HTTK | B40: =(B39-1)*60000/'Intermediate Sums'!$G9 -> 233.46303 | C40: =(C39-1)*60000/'Intermediate Sums'!$G9 -> 233.46303 | D40: =(D39-1)*60000/'Intermediate Sums'!$G9 -> 233.46303 | E40: =(E39-1)*60000/'Intermediate Sums'!$G9 -> 350.19455 | F40: =(F39-1)*60000/'Intermediate Sums'!$G9 -> 350.19455 | G40: =(G39-1)*60000/'Intermediate Sums'!$G9 -> 350.19455 | H40: =(H39-1)*60000/'Intermediate Sums'!$G9 -> 466.92607
A42: Gun 1 HSD | B42: 0 | C42: 10 | D42: 20 | E42: 35 | F42: 50 | G42: 70 | H42: 80
B43: =B49*('Intermediate Sums'!$H$2+'Intermediate Sums'!$B$4) -> 44.756 | C43: =C49*('Intermediate Sums'!$H$2+'Intermediate Sums'!$B$4) -> 33.5 | D43: =D49*('Intermediate Sums'!$H$2+'Intermediate Sums'!$B$4) -> 33.5 | E43: =E49*('Intermediate Sums'!$H$2+'Intermediate Sums'!$B$4) -> 26.8 | F43: =F49*('Intermediate Sums'!$H$2+'Intermediate Sums'!$B$4) -> 22.378 | G43: =G49*('Intermediate Sums'!$H$2+'Intermediate Sums'!$B$4) -> 22.378 | H43: =H49*('Intermediate Sums'!$H$2+'Intermediate Sums'!$B$4) -> 19.162
A45: Gun 2 HSD | B45: 0 | C45: 10 | D45: 20 | E45: 35 | F45: 50 | G45: 70 | H45: 80
B46: =B52*('Intermediate Sums'!$H$9+'Intermediate Sums'!$B$11) -> 33.5 | C46: =C52*('Intermediate Sums'!$H$9+'Intermediate Sums'!$B$11) -> 33.5 | D46: =D52*('Intermediate Sums'!$H$9+'Intermediate Sums'!$B$11) -> 33.5 | E46: =E52*('Intermediate Sums'!$H$9+'Intermediate Sums'!$B$11) -> 26.8 | F46: =F52*('Intermediate Sums'!$H$9+'Intermediate Sums'!$B$11) -> 26.8 | G46: =G52*('Intermediate Sums'!$H$9+'Intermediate Sums'!$B$11) -> 26.8 | H46: =H52*('Intermediate Sums'!$H$9+'Intermediate Sums'!$B$11) -> 22.378
A48: Gun 1 BDam | B48: 0 | C48: 10 | D48: 20 | E48: 35 | F48: 50 | G48: 70 | H48: 80
B49: =(HLOOKUP(B$48,'Intermediate Sums'!$I$1:$O$2,2,true)) -> 33.4 | C49: =(HLOOKUP(C$48,'Intermediate Sums'!$I$1:$O$2,2,true)) -> 25 | D49: =(HLOOKUP(D$48,'Intermediate Sums'!$I$1:$O$2,2,true)) -> 25 | E49: =(HLOOKUP(E$48,'Intermediate Sums'!$I$1:$O$2,2,true)) -> 20 | F49: =(HLOOKUP(F$48,'Intermediate Sums'!$I$1:$O$2,2,true)) -> 16.7 | G49: =(HLOOKUP(G$48,'Intermediate Sums'!$I$1:$O$2,2,true)) -> 16.7 | H49: =(HLOOKUP(H$48,'Intermediate Sums'!$I$1:$O$2,2,true)) -> 14.3
...

Sheet Data
B1: MV | C1: Drag | D1: D Bonus | E1: E Bonus | F1: S Malus | G1: RoF | H1: HS Mult | I1: 0 | J1: 10 | K1: 20 | L1: 35 | M1: 50 | N1: 70 | O1: 80
A2: M433 | B2: 670 | C2: 0.0025 | D2: 0.04 | E2: 1.25 | F2: 0.8 | G2: 830 | H2: 1.34 | I2: 25 | J2: 25 | K2: 25 | L2: 20 | M2: 20 | N2: 20 | O2: 16.7
A3: B364A4 | B3: 780 | C3: 0.0025 | D3: 0.04 | E3: 1.25 | F3: 0.8 | G3: 720 | H3: 1.34 | I3: 25 | J3: 25 | K3: 25 | L3: 20 | M3: 20 | N3: 20 | O3: 16.7
A4: SOR-556 MK2 | B4: 800 | C4: 0.0025 | D4: 0.04 | E4: 1.25 | F4: 0.8 | G4: 568 | H4: 1.34 | I4: 25 | J4: 25 | K4: 25 | L4: 20 | M4: 20 | N4: 20 | O4: 16.7
A5: AK4D | B5: 720 | C5: 0.0025 | D5: 0.04 | E5: 1.25 | F5: 0.8 | G5: 514 | H5: 1.34 | I5: 33.4 | J5: 33.4 | K5: 33.4 | L5: 25 | M5: 25 | N5: 25 | O5: 20
A6: TR-7 | B6: 648 | C6: 0.0025 | D6: 0.04 | E6: 1.25 | F6: 0.8 | G6: 720 | H6: 1.34 | I6: 33.4 | J6: 33.4 | K6: 33.4 | L6: 25 | M6: 25 | N6: 25 | O6: 20
A7: KORD 6P67 | B7: 760 | C7: 0.0025 | D7: 0.04 | E7: 1.25 | F7: 0.8 | G7: 900 | H7: 1.34 | I7: 20 | J7: 20 | K7: 20 | L7: 16.7 | M7: 16.7 | N7: 16.7 | O7: 14.3
A8: NVO-228E | B8: 671 | C8: 0.0025 | D8: 0.04 | E8: 1.25 | F8: 0.8 | G8: 654 | H8: 1.34 | I8: 33.4 | J8: 27.3 | K8: 27.3 | L8: 21.4 | M8: 20 | N8: 20 | O8: 16.7
A9: L85A3 | B9: 814 | C9: 0.0025 | D9: 0.04 | E9: 1.25 | F9: 0.8 | G9: 635 | H9: 1.34 | I9: 25 | J9: 25 | K9: 25 | L9: 20 | M9: 20 | N9: 20 | O9: 16.7
A10: M4A1 | B10: 630 | C10: 0.0025 | D10: 0.04 | E10: 1.25 | F10: 0.8 | G10: 900 | H10: 1.34 | I10: 25 | J10: 21.4 | K10: 21.4 | L10: 17.8 | M10: 16.7 | N10: 16.7 | O10: 14.3
A11: M277 | B11: 624 | C11: 0.0025 | D11: 0.04 | E11: 1.25 | F11: 0.8 | G11: 720 | H11: 1.34 | I11: 25 | J11: 25 | K11: 25 | L11: 25 | M11: 25 | N11: 25 | O11: 20
A12: AK-205 | B12: 737 | C12: 0.0025 | D12: 0.04 | E12: 1.25 | F12: 0.8 | G12: 720 | H12: 1.34 | I12: 20 | J12: 17.8 | K12: 17.8 | L12: 15 | M12: 14.3 | N12: 14.3 | O12: 12.5
A13: M417 A2 | B13: 600 | C13: 0.0025 | D13: 0.04 | E13: 1.25 | F13: 0.8 | G13: 654 | H13: 1.34 | I13: 33.4 | J13: 27.3 | K13: 27.3 | L13: 21.4 | M13: 20 | N13: 20 | O13: 16.7
... A42: GGH-22 | B42: 400 | C42: 0.0025 | D42: 0.04 | E42: 1.25 | F42: 0.8 | G42: 360 | H42: 1.34 | I42: 25 | J42: 21 | K42: 21 | L42: 18 | M42: 17 | N42: 17 | O42: 14

Sheet Define
A1: Tickrate: | B1: 60
A2: ms/tick | B2: =1000/B1 -> 16.666667
A5: Ammo Types | B5: H Bonus | C5: D Bonus
A6: Normal | B6: 0 | C6: 1
A7: HP | B7: 0.25 | C7: 1
A8: Synth | B8: 0.5 | C8: 1
A9: Match | B9: 0 | C9: 0.04
A11: Barrel Types | B11: V Mod
A12: Normal | B12: 1
A13: Extended | B13: 1.25
A14: Short | B14: 0.8
